<mujoco model="SpotMicroAI">
  <default>
    <default class="robot">
      <default class="motor">
        <joint />
        <motor />
      </default>
      <default class="visual">
        <geom material="visualgeom" contype="0" conaffinity="0" group="2" />
      </default>
      <default class="collision">
        <geom material="collision_material" condim="3" contype="0" conaffinity="1" priority="1" group="1" solref="0.005 1" solimp="0.99 0.999 1e-05" friction="1 0.01 0.01" />
      </default>
    </default>
  </default>

  <compiler angle="radian" />

  <asset>
    <material name="yellow" rgba="0.92 0.83 0.0 1" />
    <material name="black" rgba="0.1 0.1 0.1 1" />
    <material name="grey" rgba="0.6 0.6 0.6 1" />
    <material name="default_material" rgba="0.7 0.7 0.7 1" />
    <material name="collision_material" rgba="1.0 0.28 0.1 0.9" />
    <mesh name="mainbody.stl" file="../Parts/mainbody.stl" />
    <mesh name="backpart.stl" file="../Parts/backpart.stl" />
    <mesh name="frontpart.stl" file="../Parts/frontpart.stl" />
    <mesh name="lshoulder.stl" file="../Parts/lshoulder.stl" />
    <mesh name="larm.stl" file="../Parts/larm.stl" />
    <mesh name="larm_cover.stl" file="../Parts/larm_cover.stl" />
    <mesh name="lfoot.stl" file="../Parts/lfoot.stl" />
    <mesh name="foot.stl" file="../STL/files/foot.stl" />
    <mesh name="rshoulder.stl" file="../Parts/rshoulder.stl" />
    <mesh name="rarm.stl" file="../Parts/rarm.stl" />
    <mesh name="rarm_cover.stl" file="../Parts/rarm_cover.stl" />
    <mesh name="rfoot.stl" file="../Parts/rfoot.stl" />
  </asset>

  <worldbody>
    <body name="base_link" pos="0.00000000 0.00000000 0.25500000" quat="1 0 0 0" childclass="robot">
      <freejoint name="floating_base" />
      <geom name="base_link_collision" pos="0 0 0" quat="1.0 0.0 0.0 0.0" type="box" size="0.07 0.055 0.035" class="collision" />
      <geom name="base_link_visual" pos="-0.045 -0.060 -0.015" quat="1.0 0.0 0.0 0.0" material="black" type="mesh" mesh="mainbody.stl" scale="0.001 0.001 0.001" class="visual" />
      <body name="rear_link" pos="0 0 0" quat="1 0 0 0">
        <inertial mass="0.20" diaginertia="100.0 100.0 100.0" />
        <geom name="rear_link_collision" pos="0.135 0 0" quat="1.0 0.0 0.0 0.0" type="box" size="0.02 0.055 0.035" class="collision" />
        <geom name="rear_link_visual" pos="-0.040 -0.060 -0.0140" quat="1.0 0.0 0.0 0.0" material="yellow" type="mesh" mesh="backpart.stl" scale="0.001 0.001 0.001" class="visual" />
      </body>
      <body name="front_link" pos="0 0 0" quat="1 0 0 0">
        <inertial mass="0.20" diaginertia="100.0 100.0 100.0" />
        <geom name="front_link_collision" pos="-0.145 0 0" quat="1.0 0.0 0.0 0.0" type="box" size="0.029 0.055 0.035" class="collision" />
        <geom name="front_link_visual" pos="-0.040 -0.060 -0.0140" quat="1.0 0.0 0.0 0.0" material="yellow" type="mesh" mesh="frontpart.stl" scale="0.001 0.001 0.001" class="visual" />
      </body>
      <body name="front_left_shoulder_link" pos="-0.093 -0.036 0" quat="1.0 0.0 0.0 0.0">
        <joint name="front_left_shoulder" type="hinge" ref="0.0" class="motor" range="-0.548 0.548" axis="1 0 0" />
        <inertial mass="0.10" diaginertia="100.0 100.0 100.0" />
        <geom name="front_left_shoulder_link_collision" pos="0 0 0" quat="1.0 0.0 0.0 0.0" type="box" size="0.022 0.019 0.035" class="collision" />
        <geom name="front_left_shoulder_link_visual" pos="-0.135 -0.02 -0.01" quat="1.0 0.0 0.0 0.0" material="black" type="mesh" mesh="lshoulder.stl" scale="0.001 0.001 0.001" class="visual" />
        <body name="front_left_leg_link" pos="0 -0.052 0" quat="1.0 0.0 0.0 0.0">
          <joint name="front_left_leg" type="hinge" ref="0.0" class="motor" range="-2.666 1.548" axis="0 1 0" />
          <inertial mass="0.15" diaginertia="1000.0 1000.0 1000.0" />
          <geom name="front_left_leg_link_collision" pos="0.0 0.0 -0.050" quat="1.0 0.0 0.0 0.0" type="box" size="0.014 0.018 0.06" class="collision" />
          <geom name="front_left_leg_link_visual" pos="-0.125 0.04 -0.02" quat="1.0 0.0 0.0 0.0" material="black" type="mesh" mesh="larm.stl" scale="0.001 0.001 0.001" class="visual" />
          <body name="front_left_leg_link_cover" pos="0 0 0" quat="1.0 0.0 0.0 0.0">
            <geom name="front_left_leg_link_cover_visual" pos="-0.125 0.04 -0.02" quat="1.0 0.0 0.0 0.0" material="yellow" type="mesh" mesh="larm_cover.stl" scale="0.001 0.001 0.001" class="visual" />
          </body>
          <body name="front_left_foot_link" pos="-0.01 0 -0.12" quat="1.0 0.0 0.0 0.0">
            <joint name="front_left_foot" type="hinge" ref="0.0" class="motor" range="-0.1 2.59" axis="0 1 0" />
            <inertial mass="0.1" diaginertia="1000.0 1000.0 1000.0" />
            <geom name="front_left_foot_link_collision" pos="0.0 0.0 -0.050" quat="1.0 0.0 0.0 0.0" type="box" size="0.013 0.01 0.0575" class="collision" />
            <geom name="front_left_foot_link_visual" pos="-0.120 0.04 0.1" quat="1.0 0.0 0.0 0.0" material="black" type="mesh" mesh="lfoot.stl" scale="0.001 0.001 0.001" class="visual" />
            <body name="front_left_toe_link" pos="0 0 -0.115" quat="1.0 0.0 0.0 0.0">
              <inertial mass="0.05" diaginertia="1000.0 1000.0 1000.0" />
              <geom name="front_left_toe_link_collision" pos="0 0 0" quat="1.0 0.0 0.0 0.0" type="sphere" size="0.02" class="collision" />
              <geom name="front_left_toe_link_visual" pos="0 -0.01 0" quat="0.9800566431496228 0.0 -0.1987183338755962 0.0" material="grey" type="mesh" mesh="foot.stl" scale="0.001 0.001 0.001" class="visual" />
            </body>
          </body>
        </body>
      </body>
      <body name="front_right_shoulder_link" pos="-0.093 0.036 0" quat="1.0 0.0 0.0 0.0">
        <joint name="front_right_shoulder" type="hinge" ref="0.0" class="motor" range="-0.548 0.548" axis="1 0 0" />
        <inertial mass="0.10" diaginertia="100.0 100.0 100.0" />
        <geom name="front_right_shoulder_link_collision" pos="0 0 0" quat="1.0 0.0 0.0 0.0" type="box" size="0.022 0.019 0.035" class="collision" />
        <geom name="front_right_shoulder_link_visual" pos="-0.135 -0.09 -0.01" quat="1.0 0.0 0.0 0.0" material="black" type="mesh" mesh="rshoulder.stl" scale="0.001 0.001 0.001" class="visual" />
        <body name="front_right_leg_link" pos="0 0.052 0" quat="1.0 0.0 0.0 0.0">
          <joint name="front_right_leg" type="hinge" ref="0.0" class="motor" range="-2.666 1.548" axis="0 1 0" />
          <inertial mass="0.15" diaginertia="1000.0 1000.0 1000.0" />
          <geom name="front_right_leg_link_collision" pos="0.0 0.0 -0.050" quat="1.0 0.0 0.0 0.0" type="box" size="0.014 0.018 0.06" class="collision" />
          <geom name="front_right_leg_link_visual" pos="-0.125 -0.15 -0.02" quat="1.0 0.0 0.0 0.0" material="black" type="mesh" mesh="rarm.stl" scale="0.001 0.001 0.001" class="visual" />
          <body name="front_right_leg_link_cover" pos="0 0 0" quat="1.0 0.0 0.0 0.0">
            <geom name="front_right_leg_link_cover_visual" pos="-0.125 -0.15 -0.02" quat="1.0 0.0 0.0 0.0" material="yellow" type="mesh" mesh="rarm_cover.stl" scale="0.001 0.001 0.001" class="visual" />
          </body>
          <body name="front_right_foot_link" pos="-0.01 0 -0.12" quat="1.0 0.0 0.0 0.0">
            <joint name="front_right_foot" type="hinge" ref="0.0" class="motor" range="-0.1 2.59" axis="0 1 0" />
            <inertial mass="0.1" diaginertia="1000.0 1000.0 1000.0" />
            <geom name="front_right_foot_link_collision" pos="0.0 0.0 -0.050" quat="1.0 0.0 0.0 0.0" type="box" size="0.013 0.01 0.0575" class="collision" />
            <geom name="front_right_foot_link_visual" pos="-0.120 -0.15 0.1" quat="1.0 0.0 0.0 0.0" material="black" type="mesh" mesh="rfoot.stl" scale="0.001 0.001 0.001" class="visual" />
            <body name="front_right_toe_link" pos="0 0 -0.115" quat="1.0 0.0 0.0 0.0">
              <inertial mass="0.05" diaginertia="1000.0 1000.0 1000.0" />
              <geom name="front_right_toe_link_collision" pos="0 0 0" quat="1.0 0.0 0.0 0.0" type="sphere" size="0.02" class="collision" />
              <geom name="front_right_toe_link_visual" pos="0 -0.01 0" quat="0.9800566431496228 0.0 -0.1987183338755962 0.0" material="grey" type="mesh" mesh="foot.stl" scale="0.001 0.001 0.001" class="visual" />
            </body>
          </body>
        </body>
      </body>
      <body name="rear_left_shoulder_link" pos="0.093 -0.036 0" quat="1.0 0.0 0.0 0.0">
        <joint name="rear_left_shoulder" type="hinge" ref="0.0" class="motor" range="-0.548 0.548" axis="1 0 0" />
        <inertial mass="0.10" diaginertia="100.0 100.0 100.0" />
        <geom name="rear_left_shoulder_link_collision" pos="0 0 0" quat="1.0 0.0 0.0 0.0" type="box" size="0.022 0.019 0.035" class="collision" />
        <geom name="rear_left_shoulder_link_visual" pos="-0.135 -0.02 -0.01" quat="1.0 0.0 0.0 0.0" material="black" type="mesh" mesh="lshoulder.stl" scale="0.001 0.001 0.001" class="visual" />
        <body name="rear_left_leg_link" pos="0 -0.052 0" quat="1.0 0.0 0.0 0.0">
          <joint name="rear_left_leg" type="hinge" ref="0.0" class="motor" range="-2.666 1.548" axis="0 1 0" />
          <inertial mass="0.15" diaginertia="1000.0 1000.0 1000.0" />
          <geom name="rear_left_leg_link_collision" pos="0.0 0.0 -0.050" quat="1.0 0.0 0.0 0.0" type="box" size="0.014 0.018 0.06" class="collision" />
          <geom name="rear_left_leg_link_visual" pos="-0.125 0.04 -0.02" quat="1.0 0.0 0.0 0.0" material="black" type="mesh" mesh="larm.stl" scale="0.001 0.001 0.001" class="visual" />
          <body name="rear_left_leg_link_cover" pos="0 0 0" quat="1.0 0.0 0.0 0.0">
            <geom name="rear_left_leg_link_cover_visual" pos="-0.125 0.04 -0.02" quat="1.0 0.0 0.0 0.0" material="yellow" type="mesh" mesh="larm_cover.stl" scale="0.001 0.001 0.001" class="visual" />
          </body>
          <body name="rear_left_foot_link" pos="-0.01 0 -0.12" quat="1.0 0.0 0.0 0.0">
            <joint name="rear_left_foot" type="hinge" ref="0.0" class="motor" range="-0.1 2.59" axis="0 1 0" />
            <inertial mass="0.1" diaginertia="1000.0 1000.0 1000.0" />
            <geom name="rear_left_foot_link_collision" pos="0.0 0.0 -0.050" quat="1.0 0.0 0.0 0.0" type="box" size="0.013 0.01 0.0575" class="collision" />
            <geom name="rear_left_foot_link_visual" pos="-0.120 0.04 0.1" quat="1.0 0.0 0.0 0.0" material="black" type="mesh" mesh="lfoot.stl" scale="0.001 0.001 0.001" class="visual" />
            <body name="rear_left_toe_link" pos="0 0 -0.115" quat="1.0 0.0 0.0 0.0">
              <inertial mass="0.05" diaginertia="1000.0 1000.0 1000.0" />
              <geom name="rear_left_toe_link_collision" pos="0 0 0" quat="1.0 0.0 0.0 0.0" type="sphere" size="0.02" class="collision" />
              <geom name="rear_left_toe_link_visual" pos="0 -0.01 0" quat="0.9800566431496228 0.0 -0.1987183338755962 0.0" material="grey" type="mesh" mesh="foot.stl" scale="0.001 0.001 0.001" class="visual" />
            </body>
          </body>
        </body>
      </body>
      <body name="rear_right_shoulder_link" pos="0.093 0.036 0" quat="1.0 0.0 0.0 0.0">
        <joint name="rear_right_shoulder" type="hinge" ref="0.0" class="motor" range="-0.548 0.548" axis="1 0 0" />
        <inertial mass="0.10" diaginertia="100.0 100.0 100.0" />
        <geom name="rear_right_shoulder_link_collision" pos="0 0 0" quat="1.0 0.0 0.0 0.0" type="box" size="0.022 0.019 0.035" class="collision" />
        <geom name="rear_right_shoulder_link_visual" pos="-0.135 -0.09 -0.01" quat="1.0 0.0 0.0 0.0" material="black" type="mesh" mesh="rshoulder.stl" scale="0.001 0.001 0.001" class="visual" />
        <body name="rear_right_leg_link" pos="0 0.052 0" quat="1.0 0.0 0.0 0.0">
          <joint name="rear_right_leg" type="hinge" ref="0.0" class="motor" range="-2.666 1.548" axis="0 1 0" />
          <inertial mass="0.15" diaginertia="1000.0 1000.0 1000.0" />
          <geom name="rear_right_leg_link_collision" pos="0.0 0.0 -0.050" quat="1.0 0.0 0.0 0.0" type="box" size="0.014 0.018 0.06" class="collision" />
          <geom name="rear_right_leg_link_visual" pos="-0.125 -0.15 -0.02" quat="1.0 0.0 0.0 0.0" material="black" type="mesh" mesh="rarm.stl" scale="0.001 0.001 0.001" class="visual" />
          <body name="rear_right_leg_link_cover" pos="0 0 0" quat="1.0 0.0 0.0 0.0">
            <geom name="rear_right_leg_link_cover_visual" pos="-0.125 -0.15 -0.02" quat="1.0 0.0 0.0 0.0" material="yellow" type="mesh" mesh="rarm_cover.stl" scale="0.001 0.001 0.001" class="visual" />
          </body>
          <body name="rear_right_foot_link" pos="-0.01 0 -0.12" quat="1.0 0.0 0.0 0.0">
            <joint name="rear_right_foot" type="hinge" ref="0.0" class="motor" range="-0.1 2.59" axis="0 1 0" />
            <inertial mass="0.1" diaginertia="1000.0 1000.0 1000.0" />
            <geom name="rear_right_foot_link_collision" pos="0.0 0.0 -0.050" quat="1.0 0.0 0.0 0.0" type="box" size="0.013 0.01 0.0575" class="collision" />
            <geom name="rear_right_foot_link_visual" pos="-0.120 -0.15 0.1" quat="1.0 0.0 0.0 0.0" material="black" type="mesh" mesh="rfoot.stl" scale="0.001 0.001 0.001" class="visual" />
            <body name="rear_right_toe_link" pos="0 0 -0.115" quat="1.0 0.0 0.0 0.0">
              <inertial mass="0.05" diaginertia="1000.0 1000.0 1000.0" />
              <geom name="rear_right_toe_link_collision" pos="0 0 0" quat="1.0 0.0 0.0 0.0" type="sphere" size="0.02" class="collision" />
              <geom name="rear_right_toe_link_visual" pos="0 -0.01 0" quat="0.9800566431496228 0.0 -0.1987183338755962 0.0" material="grey" type="mesh" mesh="foot.stl" scale="0.001 0.001 0.001" class="visual" />
            </body>
          </body>
        </body>
      </body>
      <site name="base_link_site" pos="0 0 0" quat="1 0 0 0" />
      <camera name="front_camera" mode="track" fovy="90.0" quat="4.329637285359678e-17 4.329637285359677e-17 0.7071067811865475 0.7071067811865476" pos="0.0 2.0 0.5" />
      <camera name="side_camera" mode="track" fovy="90.0" quat="-0.5 -0.4999999999999999 0.5 0.5000000000000001" pos="-2.0 0.0 0.5" />
    </body>
  </worldbody>

  <actuator>
    <motor name="front_left_shoulder_ctrl" joint="front_left_shoulder" class="motor" />
    <motor name="front_left_leg_ctrl" joint="front_left_leg" class="motor" />
    <motor name="front_left_foot_ctrl" joint="front_left_foot" class="motor" />
    <motor name="front_right_shoulder_ctrl" joint="front_right_shoulder" class="motor" />
    <motor name="front_right_leg_ctrl" joint="front_right_leg" class="motor" />
    <motor name="front_right_foot_ctrl" joint="front_right_foot" class="motor" />
    <motor name="rear_left_shoulder_ctrl" joint="rear_left_shoulder" class="motor" />
    <motor name="rear_left_leg_ctrl" joint="rear_left_leg" class="motor" />
    <motor name="rear_left_foot_ctrl" joint="rear_left_foot" class="motor" />
    <motor name="rear_right_shoulder_ctrl" joint="rear_right_shoulder" class="motor" />
    <motor name="rear_right_leg_ctrl" joint="rear_right_leg" class="motor" />
    <motor name="rear_right_foot_ctrl" joint="rear_right_foot" class="motor" />
  </actuator>

  <contact>
    <exclude body1="base_link" body2="rear_link" />
    <exclude body1="base_link" body2="front_link" />
    <exclude body1="base_link" body2="front_left_shoulder_link" />
    <exclude body1="front_left_shoulder_link" body2="front_left_leg_link" />
    <exclude body1="front_left_leg_link" body2="front_left_foot_link" />
    <exclude body1="front_left_foot_link" body2="front_left_toe_link" />
    <exclude body1="base_link" body2="front_right_shoulder_link" />
    <exclude body1="front_right_shoulder_link" body2="front_right_leg_link" />
    <exclude body1="front_right_leg_link" body2="front_right_foot_link" />
    <exclude body1="front_right_foot_link" body2="front_right_toe_link" />
    <exclude body1="base_link" body2="rear_left_shoulder_link" />
    <exclude body1="rear_left_shoulder_link" body2="rear_left_leg_link" />
    <exclude body1="rear_left_leg_link" body2="rear_left_foot_link" />
    <exclude body1="rear_left_foot_link" body2="rear_left_toe_link" />
    <exclude body1="base_link" body2="rear_right_shoulder_link" />
    <exclude body1="rear_right_shoulder_link" body2="rear_right_leg_link" />
    <exclude body1="rear_right_leg_link" body2="rear_right_foot_link" />
    <exclude body1="rear_right_foot_link" body2="rear_right_toe_link" />
  </contact>

  <sensor>
    <framepos name="base_link_site_pos" objtype="site" objname="base_link_site" />
    <framequat name="base_link_site_quat" objtype="site" objname="base_link_site" />
    <framelinvel name="base_link_site_linvel" objtype="site" objname="base_link_site" />
    <frameangvel name="base_link_site_angvel" objtype="site" objname="base_link_site" />
    <velocimeter name="base_link_site_vel" site="base_link_site" />
  </sensor>
</mujoco>